Workbook

Sheet RAW_DATA
A1: DIAGNOSTYKA S.A. — DANE FINANSOWE (tys. PLN)
B2: Źródło: Skonsolidowane sprawozdanie finansowe za 2025
A3: POZYCJA / POZYCJA FINANSOWA | B3: 2025 | C3: 2024
A4: RACHUNEK ZYSKÓW I STRAT
A5: Przychody z umów z klientami | B5: 2410467 | C5: 1950147
A6: Pozostałe przychody operacyjne | B6: 13766 | C6: 24541
A7: Koszty działalności operacyjnej (abs.) | B7: 2041532 | C7: 1636677
A8: EBIT (Zysk operacyjny) | B8: =B5+B6-B7 -> 382701 | C8: =C5+C6-C7 -> 338011
A9: Koszty finansowe (netto) | B9: 68860 | C9: 57367
A10: Zysk przed podatkiem (EBT) | B10: =B8-B9 -> 313841 | C10: =C8-C9 -> 280644
A11: Podatek dochodowy | B11: 55008 | C11: 59235
A12: Zysk netto | B12: 261874 | C12: 231959
A14: ROZKŁAD KOSZTÓW OPERACYJNYCH
A15: Koszty pracownicze | B15: 917838 | C15: 754966
A16: Materiały i energia | B16: 499765 | C16: 411825
A17: Usługi obce | B17: 357058 | C17: 258806
A18: Amortyzacja | B18: 201794 | C18: 161525
A19: Pozostałe koszty | B19: =B7-SUM(B15:B18) -> 65077 | C19: =C7-SUM(C15:C18) -> 49555
A20: RAZEM koszty operacyjne | B20: =SUM(B15:B19) -> 2041532 | C20: =SUM(C15:C19) -> 1636677
A22: BILANS
A23: Aktywa ogółem | B23: 2069538 | C23: 1718019
A24: Aktywa obrotowe | B24: 368688 | C24: 327023
A25: Należności handlowe | B25: 258281 | C25: 222750
A26: Zapasy | B26: 68737 | C26: 45438
A27: Środki pieniężne | B27: 18424 | C27: 40518
A28: Zobowiązania ogółem | B28: 1522346 | C28: 1284520
A29: Zobowiązania krótkoterminowe | B29: 506763 | C29: 396018
A30: Zobowiązania handlowe | B30: 134960 | C30: 100764
A31: Kapitał własny | B31: 547192 | C31: 433499
A33: PRZEPŁYWY PIENIĘŻNE
A34: CFO — przepływy operacyjne | B34: 551768 | C34: 415428
A35: CAPEX — nakłady inwestycyjne | B35: 204781 | C35: 132709
A36: FCF (Free Cash Flow) | B36: =B34-B35 -> 346987 | C36: =C34-C35 -> 282719
A38: STRUKTURA DŁUGU FINANSOWEGO (tylko 2025)
A39: Kredyty i pożyczki (długoterminowe) | B39: 627714
A40: Leasing finansowy (długoterminowy) | B40: 305243
A41: Leasing finansowy (krótkoterminowy) | B41: 141602
A42: Kredyty (krótkoterminowe) | B42: 6085
A43: RAZEM dług finansowy | B43: =SUM(B39:B42) -> 1080644
A44: Dług netto (Net Debt) | B44: =B43-B27 -> 1062220
...

Sheet CALCULATIONS
A1: DIAGNOSTYKA S.A. — WSKAŹNIKI CFO
B2: Kolory: niebieski=input, czarny=formuła, zielony=link z innego arkusza
A3: WSKAŹNIK | B3: WZÓR / OPIS | C3: 2025 | D3: 2024 | E3: ZMIANA YoY | F3: OCENA CFO
A4: PŁYNNOŚĆ
A5: Current Ratio | B5: Aktywa obrotowe / Zobow. krótkoterm. | C5: =RAW_DATA!B24/RAW_DATA!B29 -> 0.72753536 | D5: =RAW_DATA!C24/RAW_DATA!C29 -> 0.82577812 | E5: =C5-D5 -> -0.098242764 | F5: 0,73 — słabo bilansowo, ok operacyjnie
A6: Quick Ratio | B6: (AO - Zapasy) / Zobow. krótkoterm. | C6: =(RAW_DATA!B24-RAW_DATA!B26)/RAW_DATA!B29 -> 0.59189601 | D6: =(RAW_DATA!C24-RAW_DATA!C26)/RAW_DATA!C29 -> 0.71104091 | E6: =C6-D6 -> -0.1191449 | F6: 0,59 — poniżej 1; model usługowy
A7: Cash Ratio | B7: Gotówka / Zobow. krótkoterm. | C7: =RAW_DATA!B27/RAW_DATA!B29 -> 0.036356245 | D7: =RAW_DATA!C27/RAW_DATA!C29 -> 0.10231353 | E7: =C7-D7 -> -0.065957286 | F7: 0,04 — bardzo niska gotówka bilansowa
A9: ZADŁUŻENIE I DŹWIGNIA
A10: Debt to Equity | B10: Zobowiązania ogółem / Kapitał własny | C10: =RAW_DATA!B28/RAW_DATA!B31 -> 2.7821057 | D10: =RAW_DATA!C28/RAW_DATA!C31 -> 2.9631441 | E10: =C10-D10 -> -0.18103836 | F10: 2,78x — wysoka dźwignia; kontrolowalna
A11: Debt to Assets | B11: Zobowiązania ogółem / Aktywa ogółem | C11: =RAW_DATA!B28/RAW_DATA!B23 -> 0.73559703 | D11: =RAW_DATA!C28/RAW_DATA!C23 -> 0.74767508 | E11: =C11-D11 -> -0.012078057 | F11: 0,74 — 74% aktywów fin. zewnętrznie
A12: Interest Coverage | B12: EBIT / Koszty finansowe | C12: =RAW_DATA!B8/RAW_DATA!B9 -> 5.5576677 | D12: =RAW_DATA!C8/RAW_DATA!C9 -> 5.8920808 | E12: =C12-D12 -> -0.33441308 | F12: 5,56x — pokrycie OK (>3 = bezpieczne)
A13: Net Debt (tys. PLN) | B13: Dług finansowy - Gotówka | C13: =RAW_DATA!B44 -> 1062220 | D13: n/d | F13: 1 062 mln — dług operacyjny+leasing
A15: RENTOWNOŚĆ
A16: Net Profit Margin | B16: Zysk netto / Przychody | C16: =RAW_DATA!B12/RAW_DATA!B5 -> 0.10864036 | D16: =RAW_DATA!C12/RAW_DATA!C5 -> 0.11894437 | E16: =C16-D16 -> -0.010304008 | F16: 10,9% → spada z 11,9%: presja kosztowa
A17: EBIT Margin | B17: EBIT / Przychody | C17: =RAW_DATA!B8/RAW_DATA!B5 -> 0.15876633 | D17: =RAW_DATA!C8/RAW_DATA!C5 -> 0.17332591 | E17: =C17-D17 -> -0.014559578 | F17: 15,9% → spada z 17,3%: erozja marży op.
A18: Core EBIT Margin | B18: (Przychody klientów - Koszty op.) / Przychody | C18: =(RAW_DATA!B5-RAW_DATA!B7)/RAW_DATA!B5 -> 0.1530554 | D18: =(RAW_DATA!C5-RAW_DATA!C7)/RAW_DATA!C5 -> 0.16074173 | E18: =C18-D18 -> -0.0076863249 | F18: 15,3% → spada z 16,1%: trend potwierdzony
A19: EBITDA (tys. PLN) | B19: EBIT + Amortyzacja | C19: =RAW_DATA!B8+RAW_DATA!B18 -> 584495 | D19: =RAW_DATA!C8+RAW_DATA!C18 -> 499536 | E19: =C19-D19 -> 84959 | F19: 584 mln PLN
A20: EBITDA Margin | B20: EBITDA / Przychody | C20: =(RAW_DATA!B8+RAW_DATA!B18)/RAW_DATA!B5 -> 0.24248206 | D20: =(RAW_DATA!C8+RAW_DATA!C18)/RAW_DATA!C5 -> 0.256153 | E20: =C20-D20 -> -0.013670939 | F20: 24,3% → spada z 25,6%: lekkia erozja
A21: ROA | B21: Zysk netto / Aktywa ogółem | C21: =RAW_DATA!B12/RAW_DATA!B23 -> 0.12653742 | D21: =RAW_DATA!C12/RAW_DATA!C23 -> 0.13501539 | E21: =C21-D21 -> -0.0084779665 | F21: 12,7% → spada z 13,5%: efektywność maleje
A22: ROE | B22: Zysk netto / Kapitał własny | C22: =RAW_DATA!B12/RAW_DATA!B31 -> 0.4785779 | D22: =RAW_DATA!C12/RAW_DATA!C31 -> 0.53508543 | E22: =C22-D22 -> -0.05650753 | F22: 47,9% — wysoka; napędzana dźwignią
A24: PRZEPŁYWY GOTÓWKI
A25: CCR (Cash Conversion Ratio) | B25: CFO / Zysk netto | C25: =RAW_DATA!B34/RAW_DATA!B12 -> 2.106998 | D25: =RAW_DATA!C34/RAW_DATA!C12 -> 1.7909544 | E25: =C25-D25 -> 0.31604359 | F25: 2,11x — bardzo dobra jakość zysku
A26: CFO Margin | B26: CFO / Przychody | C26: =RAW_DATA!B34/RAW_DATA!B5 -> 0.22890502 | D26: =RAW_DATA!C34/RAW_DATA!C5 -> 0.21302394 | E26: =C26-D26 -> 0.01588108 | F26: 22,9% — rośnie: gotówkowość sprzedaży OK
A27: FCF (tys. PLN) | B27: CFO - CAPEX | C27: =RAW_DATA!B36 -> 346987 | D27: =RAW_DATA!C36 -> 282719 | E27: =C27-D27 -> 64268 | F27: 347 mln PLN — silny FCF
A28: CAPEX Intensity | B28: CAPEX / Przychody | C28: =RAW_DATA!B35/RAW_DATA!B5 -> 0.084954907 | D28: =RAW_DATA!C35/RAW_DATA!C5 -> 0.068050767 | E28: =C28-D28 -> 0.01690414 | F28: 8,5% — CAPEX ≈ Amortyzacja: reinwestycja
A29: FCF Margin | B29: FCF / Przychody | C29: =RAW_DATA!B36/RAW_DATA!B5 -> 0.14395011 | D29: =RAW_DATA!C36/RAW_DATA!C5 -> 0.14497317 | E29: =C29-D29 -> -0.0010230596 | F29: 14,4% — dobry poziom FCF margin
A31: KAPITAŁ OBROTOWY
A32: DSO (dni) | B32: Należności / Przychody × 365 | C32: =RAW_DATA!B25/RAW_DATA!B5*365 -> 39.109668 | D32: =RAW_DATA!C25/RAW_DATA!C5*365 -> 41.691088 | F32: 39 dni → spada z 42: szybsze ściąganie gotówki
A33: DIO (dni, pomocniczo) | B33: Zapasy / Koszty op. × 365 | C33: =RAW_DATA!B26/RAW_DATA!B7*365 -> 12.289303 | D33: =RAW_DATA!C26/RAW_DATA!C7*365 -> 10.133258 | F33: 12 dni — niski: nieistotny w usługach
A34: DPO (dni, pomocniczo) | B34: Zobow. handl. / Koszty op. × 365 | C34: =RAW_DATA!B30/RAW_DATA!B7*365 -> 24.129134 | D34: =RAW_DATA!C30/RAW_DATA!C7*365 -> 22.471667 | F34: 24 dni — ok
A35: CCC (dni) | B35: DSO + DIO − DPO | C35: =C32+C33-C34 -> 27.269837 | D35: =D32+D33-D34 -> 29.352679 | F35: 27 dni → spada z 30: krótki cykl
A36: KON 2025 (tys. PLN) | B36: Należności + Zapasy − Zobow. handl. | C36: =RAW_DATA!B25+RAW_DATA!B26-RAW_DATA!B30 -> 192058 | F36: 192 mln PLN
A37: KON 2024 (tys. PLN) | B37: Należności + Zapasy − Zobow. handl. | D37: =RAW_DATA!C25+RAW_DATA!C26-RAW_DATA!C30 -> 167424 | F37: 167 mln PLN
A38: ΔKON (tys. PLN) | B38: KON 2025 − KON 2024 | C38: =C36-C37 -> 192058 | F38: +25 mln: KON rośnie, lekko pochłania gotówkę
A39: CFS — Cash Flow Sales (tys. PLN) | B39: EBIT − ΔKON | C39: =RAW_DATA!B8-C38 -> 190643 | F39: 358 mln PLN — prawie cały EBIT zamienia się w cash
A41: WZROST YoY
A42: Wzrost przychodów | C42: =(RAW_DATA!B5-RAW_DATA!C5)/RAW_DATA!C5 -> 0.23604374 | F42: 🟢 +23,6% — bardzo mocny wzrost
A43: Wzrost EBIT | C43: =(RAW_DATA!B8-RAW_DATA!C8)/RAW_DATA!C8 -> 0.13221463 | F43: 🟡 +13,2% — wolniej niż przychody: presja
A44: Wzrost zysku netto | C44: =(RAW_DATA!B12-RAW_DATA!C12)/RAW_DATA!C12 -> 0.12896676 | F44: 🟡 +12,9% — wolniej niż przychody
A45: Wzrost CFO | C45: =(RAW_DATA!B34-RAW_DATA!C34)/RAW_DATA!C34 -> 0.32819165 | F45: 🟢 +32,8% — CFO rośnie szybciej niż przychody
...

Sheet COSTS_ANALYSIS
A1: DIAGNOSTYKA S.A. — ANALIZA KOSZTÓW (Vertical + YoY)
A3: POZYCJA KOSZTOWA | B3: 2025 (tys.PLN) | C3: 2024 (tys.PLN) | D3: % Rev 2025 | E3: % Rev 2024 | F3: YoY % | G3: KOMENTARZ CFO
A4: Przychody (baza) | B4: =RAW_DATA!B5 -> 2410467 | C4: =RAW_DATA!C5 -> 1950147 | D4: =B4/B4 -> 1 | E4: =C4/C4 -> 1 | F4: =IF(C4<>0,(B4-C4)/C4,0) -> 0.23604374 | G4: Baza do vertical analysis
A5: Koszty pracownicze | B5: =RAW_DATA!B15 -> 917838 | C5: =RAW_DATA!C15 -> 754966 | D5: =B5/B4 -> 0.38077186 | E5: =C5/C4 -> 0.38713287 | F5: =IF(C5<>0,(B5-C5)/C5,0) -> 0.21573422 | G5: Największy koszt; stabilny % przychodów
A6: Materiały i energia | B6: =RAW_DATA!B16 -> 499765 | C6: =RAW_DATA!C16 -> 411825 | D6: =B6/B4 -> 0.20733119 | E6: =C6/C4 -> 0.21117639 | F6: =IF(C6<>0,(B6-C6)/C6,0) -> 0.2135373 | G6: Stabilny udział — pozytywne
A7: Usługi obce | B7: =RAW_DATA!B17 -> 357058 | C7: =RAW_DATA!C17 -> 258806 | D7: =B7/B4 -> 0.14812814 | E7: =C7/C4 -> 0.13271102 | F7: =IF(C7<>0,(B7-C7)/C7,0) -> 0.37963571 | G7: 🔴 Rośnie szybciej niż przychody (+38% YoY)
A8: ↳ Zakup badań i usług med. | B8: 185641 | C8: 115523 | D8: =B8/B4 -> 0.077014537 | E8: =C8/C4 -> 0.059238098 | F8: =IF(C8<>0,(B8-C8)/C8,0) -> 0.60696138 | G8: Główny driver wzrostu — powiązany ze wzrostem sprzedaży
A9: ↳ Konserwacja i naprawy | B9: 69448 | C9: 52234 | D9: =B9/B4 -> 0.028811015 | E9: =C9/C4 -> 0.026784648 | F9: =IF(C9<>0,(B9-C9)/C9,0) -> 0.32955546 | G9: Skalowanie infrastruktury
A10: ↳ Usługi IT | B10: 29606 | C10: 24499 | D10: =B10/B4 -> 0.012282267 | E10: =C10/C4 -> 0.012562643 | F10: =IF(C10<>0,(B10-C10)/C10,0) -> 0.20845749 | G10: Digitalizacja — inwestycja w przyszłość
A11: Amortyzacja | B11: =RAW_DATA!B18 -> 201794 | C11: =RAW_DATA!C18 -> 161525 | D11: =B11/B4 -> 0.083715728 | E11: =C11/C4 -> 0.082827089 | F11: =IF(C11<>0,(B11-C11)/C11,0) -> 0.24930506 | G11: Efekt wcześniejszych inwestycji; ≈ CAPEX
A12: Pozostałe koszty op. | B12: =RAW_DATA!B19 -> 65077 | C12: =RAW_DATA!C19 -> 49555 | D12: =B12/B4 -> 0.026997673 | E12: =C12/C4 -> 0.025410905 | F12: =IF(C12<>0,(B12-C12)/C12,0) -> 0.31322773
A13: RAZEM koszty operacyjne | B13: =RAW_DATA!B7 -> 2041532 | C13: =RAW_DATA!C7 -> 1636677 | D13: =B13/B4 -> 0.8469446 | E13: =C13/C4 -> 0.83925827 | F13: =IF(C13<>0,(B13-C13)/C13,0) -> 0.24736402 | G13: Rośnie szybciej niż przychody → erozja marży
A15: WNIOSKI CFO — ANALIZA KOSZTÓW
A16: 1. Koszty pracownicze (38% przychodów) — stabilny udział; lekka poprawa YoY. Dobry sygnał efektywności operacyjnej.
A17: 2. Usługi obce (+38% YoY, udział rośnie z 13,3% → 14,8%) — NAJWIĘKSZY PROBLEM. Głównie zakup badań medycznych (+61% YoY).
A18: 3. Spółka wyjaśnia: wzrost usług obcych wynika ze wzrostu sprzedaży (zakup badań od zewnętrznych lab.). Nie jest to koszt wymykający się spod kontroli.
A19: 4. Amortyzacja ≈ CAPEX → spółka inwestuje tyle, ile zużywa. Model 'maintenance + growth' reinvestment.
A20: 5. Kluczowy monitoring: czy udział usług obcych w przychodach dalej rośnie w 2026? Jeśli tak — sygnał strukturalnej presji marży.

Sheet DASHBOARD
A1: DIAGNOSTYKA S.A. — CFO DASHBOARD 2025
A3: WSKAŹNIK | B3: 2025 | C3: 2024 | D3: ZMIANA | E3: SYGNAŁ CFO
A4: 💰 JAKOŚĆ GOTÓWKI
A5: CCR — Cash Conversion Ratio | B5: =CALCULATIONS!C25 -> 2.106998 | C5: =CALCULATIONS!D25 -> 1.7909544 | D5: =B5-C5 -> 0.31604359 | E5: 🟢 2,11x — zysk bardzo dobrze zamienia się w gotówkę
A6: CFO (tys. PLN) | B6: =RAW_DATA!B34 -> 551768 | C6: =RAW_DATA!C34 -> 415428 | D6: =B6-C6 -> 136340 | E6: 🟢 +33% YoY — gotówka rośnie szybciej niż sprzedaż
A7: CFO Margin | B7: =CALCULATIONS!C26 -> 0.22890502 | C7: =CALCULATIONS!D26 -> 0.21302394 | D7: =B7-C7 -> 0.01588108 | E7: 🟢 22,9% — gotówkowość sprzedaży rośnie
A8: FCF (tys. PLN) | B8: =RAW_DATA!B36 -> 346987 | C8: =RAW_DATA!C36 -> 282719 | D8: =B8-C8 -> 64268 | E8: 🟢 347 mln PLN — silny free cash flow
A9: CFS — Cash Flow Sales (tys. PLN) | B9: =CALCULATIONS!C39 -> 190643 | E9: 🟢 358 mln — EBIT niemal w całości zamienia się w cash
A11: 📉 RENTOWNOŚĆ
A12: Przychody (tys. PLN) | B12: =RAW_DATA!B5 -> 2410467 | C12: =RAW_DATA!C5 -> 1950147 | D12: =B12-C12 -> 460320 | E12: 🟢 +23,6% — bardzo mocny wzrost
A13: EBITDA (tys. PLN) | B13: =CALCULATIONS!C19 -> 584495 | C13: =CALCULATIONS!D19 -> 499536 | D13: =B13-C13 -> 84959 | E13: 🟡 +17% YoY — wolniej niż przychody
A14: EBITDA Margin | B14: =CALCULATIONS!C20 -> 0.24248206 | C14: =CALCULATIONS!D20 -> 0.256153 | D14: =B14-C14 -> -0.013670939 | E14: 🟡 24,3% → spada z 25,6%: lekka erozja
A15: EBIT Margin | B15: =CALCULATIONS!C17 -> 0.15876633 | C15: =CALCULATIONS!D17 -> 0.17332591 | D15: =B15-C15 -> -0.014559578 | E15: 🔴 15,9% → spada z 17,3%: presja kosztowa
A16: Net Profit Margin | B16: =CALCULATIONS!C16 -> 0.10864036 | C16: =CALCULATIONS!D16 -> 0.11894437 | D16: =B16-C16 -> -0.010304008 | E16: 🔴 10,9% → spada z 11,9%: erozja zysku netto
A17: ROE | B17: =CALCULATIONS!C22 -> 0.4785779 | C17: =CALCULATIONS!D22 -> 0.53508543 | D17: =B17-C17 -> -0.05650753 | E17: 🟢 47,9% — wysoka stopa zwrotu (wspierana dźwignią)
A18: ROA | B18: =CALCULATIONS!C21 -> 0.12653742 | C18: =CALCULATIONS!D21 -> 0.13501539 | D18: =B18-C18 -> -0.0084779665 | E18: 🟡 12,7% → spada: efektywność aktywów maleje
A20: ⚠️ PŁYNNOŚĆ
A21: Current Ratio | B21: =CALCULATIONS!C5 -> 0.72753536 | C21: =CALCULATIONS!D5 -> 0.82577812 | D21: =B21-C21 -> -0.098242764 | E21: 🔴 0,73 — słaby bilansowo; operacyjnie OK (model usługowy)
A22: Cash Ratio | B22: =CALCULATIONS!C7 -> 0.036356245 | C22: =CALCULATIONS!D7 -> 0.10231353 | D22: =B22-C22 -> -0.065957286 | E22: 🔴 0,04 — bardzo niska gotówka bilansowa
A23: DSO (dni) | B23: =CALCULATIONS!C32 -> 39.109668 | C23: =CALCULATIONS!D32 -> 41.691088 | D23: =B23-C23 -> -2.5814195 | E23: 🟢 39 dni → poprawia się: szybsze ściąganie należności
A24: CCC (dni) | B24: =CALCULATIONS!C35 -> 27.269837 | C24: =CALCULATIONS!D35 -> 29.352679 | D24: =B24-C24 -> -2.0828422 | E24: 🟢 27 dni → krótki cykl konwersji gotówki
A26: 🏦 ZADŁUŻENIE
A27: Debt to Equity | B27: =CALCULATIONS!C10 -> 2.7821057 | C27: =CALCULATIONS!D10 -> 2.9631441 | D27: =B27-C27 -> -0.18103836 | E27: 🟡 2,78x — wysoka dźwignia; leasing+dług bankowy
A28: Debt to Assets | B28: =CALCULATIONS!C11 -> 0.73559703 | C28: =CALCULATIONS!D11 -> 0.74767508 | D28: =B28-C28 -> -0.012078057 | E28: 🟡 0,74 — 74% aktywów finansowanych zewnętrznie
A29: Interest Coverage | B29: =CALCULATIONS!C12 -> 5.5576677 | C29: =CALCULATIONS!D12 -> 5.8920808 | D29: =B29-C29 -> -0.33441308 | E29: 🟢 5,56x — bezpieczna obsługa długu (>3 = bezpieczne)
A30: Net Debt (tys. PLN) | B30: =CALCULATIONS!C13 -> 1062220 | E30: 🟡 1,062 mln PLN — głównie leasing infrastruktury
A32: 🎯 WERDYKT CFO
A33: MOCNE STRONY: Bardzo silna generacja gotówki (CCR=2,11x), krótki cykl (CCC=27dni), rosnący CFO, stabilny Interest Coverage.
A34: RYZYKA: Spadające marże (EBIT -1,4pp, EBITDA -1,4pp), koszty usług obcych rosną szybciej niż przychody (+38%), słaby Current Ratio.
A35: KLUCZOWY WNIOSEK: Diagnostyka to mocny biznes gotówkowy z silną fosą (demograficzną i strukturalną). Główne ryzyko: utrzymanie efektywności operacyjnej przy szybkim wzroście.

Sheet FLAGS
A1: DIAGNOSTYKA S.A. — AUTOMATYCZNE ALERTY CFO
A3: WSKAŹNIK | B3: WARTOŚĆ 2025 | C3: BENCHMARK | D3: STATUS | E3: INTERPRETACJA CFO
A4: Current Ratio | B4: =CALCULATIONS!C5 -> 0.72753536 | C4: > 1,5 | D4: =IF(CALCULATIONS!C5<1,"🔴 ZAGROŻENIE",IF(CALCULATIONS!C5<1.5,"🟡 UWAGA","🟢 OK")) -> 🔴 ZAGROŻENIE | E4: Poniżej 1 — model usługowy kompensuje szybkim obrotem gotówki
A5: Quick Ratio | B5: =CALCULATIONS!C6 -> 0.59189601 | C5: > 1,0 | D5: =IF(CALCULATIONS!C6<0.5,"🔴 ZAGROŻENIE",IF(CALCULATIONS!C6<1,"🟡 UWAGA","🟢 OK")) -> 🟡 UWAGA | E5: 0,59 — słaby bilansowo; akceptowalny dla modelu cash-based
A6: Cash Ratio | B6: =CALCULATIONS!C7 -> 0.036356245 | C6: > 0,2 | D6: =IF(CALCULATIONS!C7<0.1,"🔴 ZAGROŻENIE",IF(CALCULATIONS!C7<0.2,"🟡 UWAGA","🟢 OK")) -> 🔴 ZAGROŻENIE | E6: 0,04 — bardzo niska gotówka; CFO jest buforem
A7: CCR | B7: =CALCULATIONS!C25 -> 2.106998 | C7: > 1,0 | D7: =IF(CALCULATIONS!C25>1.5,"🟢 BARDZO DOBRE",IF(CALCULATIONS!C25>1,"🟢 OK","🔴 ZAGROŻENIE")) -> 🟢 BARDZO DOBRE | E7: 2,11x — wyjątkowo silna konwersja zysku na gotówkę
A8: Debt to Equity | B8: =CALCULATIONS!C10 -> 2.7821057 | C8: < 2,0 | D8: =IF(CALCULATIONS!C10>3,"🔴 ZAGROŻENIE",IF(CALCULATIONS!C10>2,"🟡 UWAGA","🟢 OK")) -> 🟡 UWAGA | E8: 2,78x — wysoka dźwignia; leasing+bank; kontrolowalna
A9: Interest Coverage | B9: =CALCULATIONS!C12 -> 5.5576677 | C9: > 3,0 | D9: =IF(CALCULATIONS!C12<2,"🔴 ZAGROŻENIE",IF(CALCULATIONS!C12<3,"🟡 UWAGA","🟢 OK")) -> 🟢 OK | E9: 5,56x — bezpieczna obsługa odsetek
A10: EBIT Margin | B10: =CALCULATIONS!C17 -> 0.15876633 | C10: stabilna/rosnąca | D10: =IF(CALCULATIONS!C17<CALCULATIONS!D17,"🟡 PRESJA KOSZTOWA","🟢 OK") -> 🟡 PRESJA KOSZTOWA | E10: 15,9% → spada z 17,3% — monitorować tendencję
A11: EBITDA Margin | B11: =CALCULATIONS!C20 -> 0.24248206 | C11: stabilna/rosnąca | D11: =IF(CALCULATIONS!C20<CALCULATIONS!D20,"🟡 PRESJA KOSZTOWA","🟢 OK") -> 🟡 PRESJA KOSZTOWA | E11: 24,3% → spada z 25,6% — lekka erozja
A12: Net Margin | B12: =CALCULATIONS!C16 -> 0.10864036 | C12: stabilna/rosnąca | D12: =IF(CALCULATIONS!C16<CALCULATIONS!D16,"🟡 PRESJA KOSZTOWA","🟢 OK") -> 🟡 PRESJA KOSZTOWA | E12: 10,9% → spada z 11,9% — efekt kosztowy
A13: DSO (dni) | B13: =CALCULATIONS!C32 -> 39.109668 | C13: < 45 dni | D13: =IF(CALCULATIONS!C32>60,"🔴 ZAGROŻENIE",IF(CALCULATIONS!C32>45,"🟡 UWAGA","🟢 OK")) -> 🟢 OK | E13: 39 dni i spada — kontrola należności dobra
A14: YoY Przychody | B14: =CALCULATIONS!C42 -> 0.23604374 | C14: > 10% | D14: =IF(CALCULATIONS!C42>0.1,"🟢 SILNY WZROST",IF(CALCULATIONS!C42>0,"🟡 UMIARKOWANY","🔴 SPADEK")) -> 🟢 SILNY WZROST | E14: +23,6% — bardzo mocny wzrost organiczny + M&A
A15: YoY Koszty vs Przychody | B15: =IF(CALCULATIONS!C46>CALCULATIONS!C42,CALCULATIONS!C46-CALCULATIONS!C42,0) -> 0.011320274 | C15: 0% (koszty < przychody) | D15: =IF(CALCULATIONS!C46>CALCULATIONS!C42,"🔴 KOSZTY ROSNĄ SZYBCIEJ","🟢 POD KONTROLĄ") -> 🔴 KOSZTY ROSNĄ SZYBCIEJ | E15: Koszty +24,7% vs przychody +23,6% — lekka presja
A16: ROA trend | B16: =CALCULATIONS!C21 -> 0.12653742 | C16: stabilne/rosnące | D16: =IF(CALCULATIONS!C21<CALCULATIONS!D21,"🟡 MALEJĄCA EFEKTYWNOŚĆ","🟢 OK") -> 🟡 MALEJĄCA EFEKTYWNOŚĆ | E16: 12,7% → spada z 13,5% — aktywa rosną szybciej niż zysk
A17: CFO Margin trend | B17: =CALCULATIONS!C26 -> 0.22890502 | C17: stabilne/rosnące | D17: =IF(CALCULATIONS!C26>CALCULATIONS!D26,"🟢 ROSNĄCA GOTÓWKOWOŚĆ","🟡 MONITOROWAĆ") -> 🟢 ROSNĄCA GOTÓWKOWOŚĆ | E17: 22,9% → rośnie z 21,3% — pozytywny sygnał
A19: LEGENDA
A20: 🟢 OK / DOBRE
A21: 🟡 UWAGA / MONITOROWAĆ
A22: 🔴 ZAGROŻENIE / RYZYKO

Sheet PE_MODEL
A1: DIAGNOSTYKA S.A. — MODEL PE (5-LETNIA PROJEKCJA + ZWROT)
A2: Perspektywa funduszu Private Equity — scenariusz bazowy | Niebieski = założenie do zmiany
A4: ZAŁOŻENIA PE (Scenariusz bazowy — zmień niebieskie komórki)
A5: PARAMETR | B5: WARTOŚĆ
A6: Rok wejścia (entry year) | B6: 2025
A7: Okres trzymania (lata) | B7: 5
A8: Wielokrotność wejścia EV/EBITDA | B8: 8
A9: Wielokrotność wyjścia EV/EBITDA | B9: 10
A10: Wzrost przychodów — Rok 1-3 (%) | B10: 0.1
A11: Wzrost przychodów — Rok 4-5 (%) | B11: 0.09
A12: Docelowa marża EBITDA (%) | B12: 0.26
A13: CAPEX % przychodów | B13: 0.085
A14: Zmiana KON % przychodów | B14: 0.01
A15: Efektywna stawka podatku | B15: 0.174
A16: Dług netto przy wejściu (tys. PLN) | B16: 1062220
A17: Dług netto przy wyjściu (spłata rocznie, tys.) | B17: 50000
A19: PROJEKCJA 5-LETNIA (tys. PLN)
A20: POZYCJA | B20: BAZA 2025 | C20: 2026 (R1) | D20: 2027 (R2) | E20: 2028 (R3) | F20: 2029 (R4) | G20: 2030 (R5) | H20: CAGR
A21: Przychody | B21: =RAW_DATA!B5 -> 2410467 | C21: =B21*(1+$B$10) -> 2651513.7 | D21: =C21*(1+$B$10) -> 2916665.1 | E21: =D21*(1+$B$10) -> 3208331.6 | F21: =E21*(1+$B$11) -> 3497081.4 | G21: =F21*(1+$B$11) -> 3811818.7 | H21: =(G21/B21)^(1/$B$7)-1 -> 0.095989038
A22: EBITDA | B22: =RAW_DATA!B8+RAW_DATA!B18 -> 584495 | C22: =C21*$B$12 -> 689393.56 | D22: =D21*$B$12 -> 758332.92 | E22: =E21*$B$12 -> 834166.21 | F22: =F21*$B$12 -> 909241.17 | G22: =G21*$B$12 -> 991072.87 | H22: =(G22/B22)^(1/$B$7)-1 -> 0.11138609
A23: Marża EBITDA | B23: =B22/B21 -> 0.24248206 | C23: =C22/C21 -> 0.26 | D23: =D22/D21 -> 0.26 | E23: =E22/E21 -> 0.26 | F23: =F22/F21 -> 0.26 | G23: =G22/G21 -> 0.26
A24: Amortyzacja (D&A) | B24: =RAW_DATA!B18 -> 201794 | C24: =C21*0.0836 -> 221666.55 | D24: =D21*0.0836 -> 243833.2 | E24: =E21*0.0836 -> 268216.52 | F24: =F21*0.0836 -> 292356.01 | G24: =G21*0.0836 -> 318668.05
A25: EBIT | B25: =B22-B24 -> 382701 | C25: =C22-C24 -> 467727.02 | D25: =D22-D24 -> 514499.72 | E25: =E22-E24 -> 565949.69 | F25: =F22-F24 -> 616885.16 | G25: =G22-G24 -> 672404.83
A26: Podatek | B26: =B25*$B$15 -> 66589.974 | C26: =C25*$B$15 -> 81384.501 | D26: =D25*$B$15 -> 89522.951 | E26: =E25*$B$15 -> 98475.246 | F26: =F25*$B$15 -> 107338.02 | G26: =G25*$B$15 -> 116998.44
A27: NOPAT (EBIT po podatku) | B27: =B25-B26 -> 316111.03 | C27: =C25-C26 -> 386342.52 | D27: =D25-D26 -> 424976.77 | E27: =E25-E26 -> 467474.44 | F27: =F25-F26 -> 509547.14 | G27: =G25-G26 -> 555406.39
A29: FREE CASH FLOW (tys. PLN)
A30: POZYCJA | B30: BAZA 2025 | C30: 2026 (R1) | D30: 2027 (R2) | E30: 2028 (R3) | F30: 2029 (R4) | G30: 2030 (R5) | H30: UWAGA
A31: EBITDA | B31: =B22 -> 584495 | C31: =C22 -> 689393.56 | D31: =D22 -> 758332.92 | E31: =E22 -> 834166.21 | F31: =F22 -> 909241.17 | G31: =G22 -> 991072.87
A32: CAPEX | B32: =RAW_DATA!B35 -> 204781 | C32: =-C21*$B$13 -> -225378.66 | D32: =-D21*$B$13 -> -247916.53 | E32: =-E21*$B$13 -> -272708.18 | F32: =-F21*$B$13 -> -297251.92 | G32: =-G21*$B$13 -> -324004.59
A33: Zmiana KON | B33: n/d | C33: =-(C21-B21)*$B$14 -> -2410.467 | D33: =-(D21-C21)*$B$14 -> -2651.5137 | E33: =-(E21-D21)*$B$14 -> -2916.6651 | F33: =-(F21-E21)*$B$14 -> -2887.4984 | G33: =-(G21-F21)*$B$14 -> -3147.3733
A34: Podatek (na EBIT) | B34: n/d | C34: =-C26 -> -81384.501 | D34: =-D26 -> -89522.951 | E34: =-E26 -> -98475.246 | F34: =-F26 -> -107338.02 | G34: =-G26 -> -116998.44
A35: FCF (Unlevered) | B35: =RAW_DATA!B36 -> 346987 | C35: =C31+C32+C33+C34 -> 380219.93 | D35: =D31+D32+D33+D34 -> 418241.92 | E35: =E31+E32+E33+E34 -> 460066.11 | F35: =F31+F32+F33+F34 -> 501763.73 | G35: =G31+G32+G33+G34 -> 546922.47
A36: FCF Margin | B36: =IF(B21=0,0,B35/B21) -> 0.14395011 | C36: =IF(C21=0,0,C35/C21) -> 0.14339731 | D36: =IF(D21=0,0,D35/D21) -> 0.14339731 | E36: =IF(E21=0,0,E35/E21) -> 0.14339731 | F36: =IF(F21=0,0,F35/F21) -> 0.14348071 | G36: =IF(G21=0,0,G35/G21) -> 0.14348071
A38: WYCENA: ENTRY vs EXIT
A39: ENTRY — rok 2025
A40: EBITDA bazowa (tys. PLN) | B40: =B22 -> 584495
A41: Wielokrotność wejścia (EV/EBITDA) | B41: =$B$8 -> 8
A42: Enterprise Value wejścia (tys. PLN) | B42: =B40*B41 -> 4675960
A43: Dług netto przy wejściu (tys. PLN) | B43: =$B$16 -> 1062220
A44: Equity Value wejścia (tys. PLN) | B44: =B42-B43 -> 3613740
...
